<?xml version="1.0" encoding="utf-8"?>
<robot name="roar">
  <link name="base_link">
    <inertial>
      <origin xyz="0.00469098688936509 -0.0777682848151969 0.324101627417335" rpy="0 0 0" />
      <mass value="10.0" />
      <inertia ixx="0.0" ixy="0.0" ixz="0.0" iyy="0.0" iyz="0.0" izz="0.0" />
    </inertial>
    <visual>
      <origin xyz="0 0 0" rpy="0 0 0" />
      <geometry>
        <mesh filename="package://roar/meshes/base_link.STL" />
      </geometry>
      <material name="">
        <color rgba="0.529411764705882 0.549019607843137 0.549019607843137 1" />
      </material>
    </visual>
    <collision>
      <origin xyz="0 0 0" rpy="0 0 0" />
      <geometry>
        <mesh filename="package://roar/meshes/base_link.STL" />
      </geometry>
    </collision>
  </link>
  <link name="rocker_rhs">
    <inertial>
      <origin xyz="0.356634879782049 0.249567425783871 0.0168797911183071" rpy="0 0 0" />
      <mass value="1.55415245354649" />
      <inertia ixx="0.00304699343681013" ixy="-0.00122725683108501" ixz="-6.78110157247864E-05" iyy="0.00431671461496656" iyz="-4.53350583239748E-05" izz="0.00469688805108083" />
    </inertial>
    <visual>
      <origin xyz="0 0 0" rpy="0 0 0" />
      <geometry>
        <mesh filename="package://roar/meshes/rocker_rhs.STL" />
      </geometry>
      <material name="">
        <color rgba="0.792156862745098 0.819607843137255 0.933333333333333 1" />
      </material>
    </visual>
    <collision>
      <origin xyz="0 0 0" rpy="0 0 0" />
      <geometry>
        <mesh filename="package://roar/meshes/rocker_rhs.STL" />
      </geometry>
    </collision>
  </link>
  <joint name="rocker_rhs_joint" type="fixed">
    <origin xyz="0.341 -0.00441357789442404 0.318458529702179" rpy="-1.5707963267949 0.0269760214941811 -1.5707963267949" />
    <parent link="base_link" />
    <child link="rocker_rhs" />
    <axis xyz="0 0 -1" />
  </joint>
  <link name="bogie_rhs">
    <inertial>
      <origin xyz="0.000413252708581058 0.147072285784854 0.121779882797586" rpy="0 0 0" />
      <mass value="2.56788752987332" />
      <inertia ixx="0.00417595671889658" ixy="-2.40383932788247E-07" ixz="7.46152900476444E-08" iyy="0.00445750777097546" iyz="-9.37581657450096E-05" izz="0.00354223475883779" />
    </inertial>
    <visual>
      <origin xyz="0 0 0" rpy="0 0 0" />
      <geometry>
        <mesh filename="package://roar/meshes/bogie_rhs.STL" />
      </geometry>
      <material name="">
        <color rgba="0.792156862745098 0.819607843137255 0.933333333333333 1" />
      </material>
    </visual>
    <collision>
      <origin xyz="0 0 0" rpy="0 0 0" />
      <geometry>
        <mesh filename="package://roar/meshes/bogie_rhs.STL" />
      </geometry>
    </collision>
  </link>
  <joint name="bogie_rhs_joint" type="fixed">
    <origin xyz="-0.224229060097619 0.165122592734234 -0.0928547999999997" rpy="0 0 -0.03" />
    <parent link="rocker_rhs" />
    <child link="bogie_rhs" />
    <axis xyz="0 0 -1" />
  </joint>
  <link name="wheel_rhs_mid">
    <inertial>
      <origin xyz="3.05311331771918E-16 -0.00031009853866483 0.0600063600245654" rpy="0 0 0" />
      <mass value="1.5976653768916" />
      <inertia ixx="0.00836783341696594" ixy="7.18283939271647E-18" ixz="-5.84071446049636E-16" iyy="0.00836775197998545" iyz="-6.24418083574133E-14" izz="0.013244679799626" />
    </inertial>
    <visual>
      <origin xyz="0 0 0" rpy="0 0 0" />
      <geometry>
        <mesh filename="package://roar/meshes/wheel_rhs_mid.STL" />
      </geometry>
      <material name="">
        <color rgba="0.298039215686275 0.298039215686275 0.298039215686275 1" />
      </material>
    </visual>
    <collision>
      <origin xyz="0 0 0" rpy="0 0 0" />
      <geometry>
        <mesh filename="package://roar/meshes/wheel_rhs_mid.STL" />
      </geometry>
    </collision>
  </link>
  <joint name="wheel_rhs_mid_joint" type="continuous">
    <origin xyz="0.229224601627686 0.160798282710695 0.105843639709434" rpy="0 0 3.12607538350607" />
    <parent link="bogie_rhs" />
    <child link="wheel_rhs_mid" />
    <axis xyz="0 0 -1" />
  </joint>
  <link name="wheel_rhs_front">
    <inertial>
      <origin xyz="-6.28397432798078E-05 -0.000299207692801798 0.0617344385469731" rpy="0 0 0" />
      <mass value="1.55166626304694" />
      <inertia ixx="0.00800333028314918" ixy="-1.61745154658915E-08" ixz="5.54140420044703E-13" iyy="0.00800325666613796" iyz="2.637538385541E-12" izz="0.0125934306153833" />
    </inertial>
    <visual>
      <origin xyz="0 0 0" rpy="0 0 0" />
      <geometry>
        <mesh filename="package://roar/meshes/wheel_rhs_front.STL" />
      </geometry>
      <material name="">
        <color rgba="0.298039215686275 0.298039215686275 0.298039215686275 1" />
      </material>
    </visual>
    <collision>
      <origin xyz="0 0 0" rpy="0 0 0" />
      <geometry>
        <mesh filename="package://roar/meshes/wheel_rhs_front.STL" />
      </geometry>
    </collision>
  </link>
  <joint name="wheel_rhs_front_joint" type="continuous">
    <origin xyz="-0.229500390800753 0.160404414952893 0.104120372913068" rpy="0 0 -3.14159265358979" />
    <parent link="bogie_rhs" />
    <child link="wheel_rhs_front" />
    <axis xyz="0 0 -1" />
  </joint>
  <link name="wheel_rhs_rear">
    <inertial>
      <origin xyz="5.16253706450698E-15 0.00015154563885042 0.0600149113817935" rpy="0 0 0" />
      <mass value="1.55167119278224" />
      <inertia ixx="0.00800323403290157" ixy="-1.03184896315713E-16" ixz="-1.94336817583681E-17" iyy="0.00800315362181799" iyz="-1.09712890180285E-10" izz="0.0125935069824427" />
    </inertial>
    <visual>
      <origin xyz="0 0 0" rpy="0 0 0" />
      <geometry>
        <mesh filename="package://roar/meshes/wheel_rhs_rear.STL" />
      </geometry>
      <material name="">
        <color rgba="0.298039215686275 0.298039215686275 0.298039215686275 1" />
      </material>
    </visual>
    <collision>
      <origin xyz="0 0 0" rpy="0 0 0" />
      <geometry>
        <mesh filename="package://roar/meshes/wheel_rhs_rear.STL" />
      </geometry>
    </collision>
  </link>
  <joint name="wheel_rhs_rear_joint" type="continuous">
    <origin xyz="0.46794017955705 0.307105950932406 0.0129798220506307" rpy="0 0 3.14159265358979" />
    <parent link="rocker_rhs" />
    <child link="wheel_rhs_rear" />
    <axis xyz="0 0 -1" />
  </joint>
  <link name="rocker_lhs">
    <inertial>
      <origin xyz="0.355676246263101 -0.251011188160812 0.114353485211955" rpy="0 0 0" />
      <mass value="1.55450623077954" />
      <inertia ixx="0.00304702979065891" ixy="0.00122725847821496" ixz="-6.7805504639355E-05" iyy="0.00431674151222301" iyz="4.53438210665476E-05" izz="0.00469693111237126" />
    </inertial>
    <visual>
      <origin xyz="0 0 0" rpy="0 0 0" />
      <geometry>
        <mesh filename="package://roar/meshes/rocker_lhs.STL" />
      </geometry>
      <material name="">
        <color rgba="0.792156862745098 0.819607843137255 0.933333333333333 1" />
      </material>
    </visual>
    <collision>
      <origin xyz="0 0 0" rpy="0 0 0" />
      <geometry>
        <mesh filename="package://roar/meshes/rocker_lhs.STL" />
      </geometry>
    </collision>
  </link>
  <joint name="rocker_lhs_joint" type="fixed">
    <origin xyz="-0.244499999999996 -0.00517486124912506 0.320045490177976" rpy="1.5707963267949 0.0269760214941811 -1.5707963267949" />
    <parent link="base_link" />
    <child link="rocker_lhs" />
    <axis xyz="0 0 1" />
  </joint>
  <link name="bogie_lhs">
    <inertial>
      <origin xyz="0.00196274820164133 -0.147059768544191 0.121779882817316" rpy="0 0 0" />
      <mass value="2.56788753304685" />
      <inertia ixx="0.0041760379642359" ixy="-4.78811399342551E-06" ixz="-1.58926496416294E-06" iyy="0.00445742650894979" iyz="9.37447259554026E-05" izz="0.00354223473986378" />
    </inertial>
    <visual>
      <origin xyz="0 0 0" rpy="0 0 0" />
      <geometry>
        <mesh filename="package://roar/meshes/bogie_lhs.STL" />
      </geometry>
      <material name="">
        <color rgba="0.792156862745098 0.819607843137255 0.933333333333333 1" />
      </material>
    </visual>
    <collision>
      <origin xyz="0 0 0" rpy="0 0 0" />
      <geometry>
        <mesh filename="package://roar/meshes/bogie_lhs.STL" />
      </geometry>
    </collision>
  </link>
  <joint name="bogie_lhs_joint" type="fixed">
    <origin xyz="-0.224947261786088 -0.16672950973041 0.00464519999999913" rpy="0 0 0" />
    <parent link="rocker_lhs" />
    <child link="bogie_lhs" />
    <axis xyz="0 0 -1" />
  </joint>
  <link name="wheel_lhs_mid">
    <inertial>
      <origin xyz="8.32667268468867E-17 0.000310098538664483 0.0600061613680265" rpy="0 0 0" />
      <mass value="1.59766537689161" />
      <inertia ixx="0.00836783341696616" ixy="1.29476733188556E-16" ixz="-2.78394080503685E-16" iyy="0.00836775197998588" iyz="-6.25104164123782E-14" izz="0.0132446797996265" />
    </inertial>
    <visual>
      <origin xyz="0 0 0" rpy="0 0 0" />
      <geometry>
        <mesh filename="package://roar/meshes/wheel_lhs_mid.STL" />
      </geometry>
      <material name="">
        <color rgba="0.298039215686275 0.298039215686275 0.298039215686275 1" />
      </material>
    </visual>
    <collision>
      <origin xyz="0 0 0" rpy="0 0 0" />
      <geometry>
        <mesh filename="package://roar/meshes/wheel_lhs_mid.STL" />
      </geometry>
    </collision>
  </link>
  <joint name="wheel_lhs_mid_joint" type="continuous">
    <origin xyz="0.232061767651008 -0.156675912982079 0.105848638897971" rpy="0 0 3.14159265358979" />
    <parent link="bogie_lhs" />
    <child link="wheel_lhs_mid" />
    <axis xyz="0 0 1" />
  </joint>
  <link name="wheel_lhs_front">
    <inertial>
      <origin xyz="4.44089209850063E-16 0.000305735786541028 0.060015644846366" rpy="0 0 0" />
      <mass value="1.55167119278224" />
      <inertia ixx="0.0080032340329016" ixy="8.92343020906058E-17" ixz="-4.04328578482084E-17" iyy="0.00800315362181802" iyz="-1.09712873056732E-10" izz="0.0125935069824427" />
    </inertial>
    <visual>
      <origin xyz="0 0 0" rpy="0 0 0" />
      <geometry>
        <mesh filename="package://roar/meshes/wheel_lhs_front.STL" />
      </geometry>
      <material name="">
        <color rgba="0.298039215686275 0.298039215686275 0.298039215686275 1" />
      </material>
    </visual>
    <collision>
      <origin xyz="0 0 0" rpy="0 0 0" />
      <geometry>
        <mesh filename="package://roar/meshes/wheel_lhs_front.STL" />
      </geometry>
    </collision>
  </link>
  <joint name="wheel_lhs_front_joint" type="continuous">
    <origin xyz="-0.226596998316561 -0.164480412414379 0.105834821721209" rpy="0 0 3.14159265358979" />
    <parent link="bogie_lhs" />
    <child link="wheel_lhs_front" />
    <axis xyz="0 0 1" />
  </joint>
  <link name="wheel_lhs_rear">
    <inertial>
      <origin xyz="3.33066907387547E-16 0.000305735305071581 0.0617344149234693" rpy="0 0 0" />
      <mass value="1.55166626304695" />
      <inertia ixx="0.00800333368012843" ixy="1.76843939308345E-16" ixz="4.18511383343929E-16" iyy="0.00800325326915781" iyz="2.69448778130305E-12" izz="0.0125934306153827" />
    </inertial>
    <visual>
      <origin xyz="0 0 0" rpy="0 0 0" />
      <geometry>
        <mesh filename="package://roar/meshes/wheel_lhs_rear.STL" />
      </geometry>
      <material name="">
        <color rgba="0.298039215686275 0.298039215686275 0.298039215686275 1" />
      </material>
    </visual>
    <collision>
      <origin xyz="0 0 0" rpy="0 0 0" />
      <geometry>
        <mesh filename="package://roar/meshes/wheel_lhs_rear.STL" />
      </geometry>
    </collision>
  </link>
  <joint name="wheel_lhs_rear_joint" type="continuous">
    <origin xyz="0.467221977868636 -0.308712867928559 0.108765573616487" rpy="0 0 3.14159265358979" />
    <parent link="rocker_lhs" />
    <child link="wheel_lhs_rear" />
    <axis xyz="0 0 1" />
  </joint>

  <!-- ROS Control plugin for Gazebo-->
  <gazebo>
    <plugin name="gazebo_ros_control" filename="libgazebo_ros_control.so"/>
    <!-- <robotNamespace>/roar</robotNamespace> -->
  </gazebo>

  <!--transmission-->
  <transmission name="wheel_lhs_front_transmission">
    <type>transmission_interface/SimpleTransmission</type>
    <joint name="wheel_lhs_front_joint">
      <hardwareInterface>hardware_interface/VelocityJointInterface</hardwareInterface>
    </joint>
    <actuator name="wheel_lhs_front_motor">
      <mechanicalReduction>1</mechanicalReduction>
    </actuator>
  </transmission>

  <transmission name="wheel_lhs_mid_transmission">
    <type>transmission_interface/SimpleTransmission</type>
    <joint name="wheel_lhs_mid_joint">
      <hardwareInterface>hardware_interface/VelocityJointInterface</hardwareInterface>
    </joint>
    <actuator name="wheel_lhs_mid_motor">
      <mechanicalReduction>1</mechanicalReduction>
    </actuator>
  </transmission>

  <transmission name="wheel_lhs_rear_transmission">
    <type>transmission_interface/SimpleTransmission</type>
    <joint name="wheel_lhs_rear_joint">
      <hardwareInterface>hardware_interface/VelocityJointInterface</hardwareInterface>
    </joint>
    <actuator name="wheel_lhs_rear_motor">
      <mechanicalReduction>1</mechanicalReduction>
    </actuator>
  </transmission>

  <transmission name="wheel_rhs_front_transmission">
    <type>transmission_interface/SimpleTransmission</type>
    <joint name="wheel_rhs_front_joint">
      <hardwareInterface>hardware_interface/VelocityJointInterface</hardwareInterface>
    </joint>
    <actuator name="wheel_rhs_front_motor">
      <mechanicalReduction>1</mechanicalReduction>
    </actuator>
  </transmission>

  <transmission name="wheel_rhs_mid_transmission">
    <type>transmission_interface/SimpleTransmission</type>
    <joint name="wheel_rhs_mid_joint">
      <hardwareInterface>hardware_interface/VelocityJointInterface</hardwareInterface>
    </joint>
    <actuator name="wheel_rhs_mid_motor">
      <mechanicalReduction>1</mechanicalReduction>
    </actuator>
  </transmission>

  <transmission name="wheel_rhs_rear_transmission">
    <type>transmission_interface/SimpleTransmission</type>
    <joint name="wheel_rhs_rear_joint">
      <hardwareInterface>hardware_interface/VelocityJointInterface</hardwareInterface>
    </joint>
    <actuator name="wheel_rhs_rear_motor">
      <mechanicalReduction>1</mechanicalReduction>
    </actuator>
  </transmission>

  <gazebo>
    <plugin name="imu_plugin" filename="libgazebo_ros_imu.so">
      <alwaysOn>true</alwaysOn>
      <bodyName>base_link</bodyName>
      <topicName>imu</topicName>
      <serviceName>imu_service</serviceName>
      <gaussianNoise>0.0</gaussianNoise>
      <updateRate>20.0</updateRate>
    </plugin>
  </gazebo>

  <!-- Adding GPS sensor from hector_gazebo_plugin-->
  <gazebo>
    <plugin name="novatel_gps_sim" filename="libhector_gazebo_ros_gps.so">
      <alwaysOn>1</alwaysOn>
      <updateRate>10.0</updateRate>
      <bodyName>base_link</bodyName>
      <topicName>gps</topicName>
      <velocityTopicName>fix_velocity</velocityTopicName>
      <drift>5.0 5.0 5.0</drift>
      <gaussianNoise>0.1 0.1 0.1</gaussianNoise>
      <velocityDrift>0 0 0</velocityDrift>
      <velocityGaussianNoise>0.1 0.1 0.1</velocityGaussianNoise>
    </plugin>
  </gazebo>

  <gazebo>
    <plugin name="magnetometer" filename="libhector_gazebo_ros_magnetic.so">
      <updateRate>20.0</updateRate>
      <bodyname>base_link</bodyname>
      <topicName>magnetometer</topicName>
      <referenceHeading>0.0</referenceHeading>
      <declination>11.4017</declination>
      <inclination>-68.5006</inclination>
      <offset>0 0 0</offset>
      <driftFrequency>0 0 0</driftFrequency>
      <gaussianNoise>0 0 0</gaussianNoise>
    </plugin>
  </gazebo>

</robot>